Workbook

Sheet Guide
A1: Menu & Parts Inventory Workbook
A3: How it works | B3: Each menu item is built from ingredients (its recipe / bill of materials). Selling an item consumes those ingredients, which drives the reorder list.
A4: Ingredients | B4: Master list of every part you buy: purchasing info, stock, reorder rules.
A5: Menu Items | B5: What you sell. Cost, margin and units sold are calculated from the recipes.
A6: Recipes | B6: One row per ingredient per menu item. To add an ingredient to an item, add a row with the Item ID, Ingredient ID and quantity.
A7: Where Used | B7: Matrix of ingredients vs. menu items - quickly see which items need a part.
A8: Procurement | B8: Reorder list grouped by supplier. Rows flagged REORDER should be purchased.
A9: Purchase Orders | B9: Orders created from the website with what has been received, damaged and is still outstanding.
A10: Receiving Log | B10: Every delivery checked in on the website: who, when, what arrived, damage, shortages and notes.
A11: Sales Log | B11: Sales recorded on the website; feeds 'Units Used' and 'Units Sold'.
A12: Staff | B12: Employees with role, hourly rate and maximum hours per week.
A13: Schedule | B13: Every shift: date, employee, start/end, hours and labor cost. OPEN = not yet assigned.
A14: Weekly Hours | B14: Hours per employee per day for one week. Change the Monday date in B1 to look at another week; over-max rows turn red.
... A20: Syncing | B20: The website rewrites this file after every change. Edits made here can be pulled into the website from its Excel tab (Import). Only blue input columns are read.

Sheet Ingredients
A1: Ingredient ID | B1: Name | C1: Category | D1: Recipe Unit | E1: Supplier | F1: Supplier SKU | G1: Package Description | H1: Qty per Package (units) | I1: Package Cost ($) | J1: Shipping per Package ($) | K1: Landed Unit Cost ($) | L1: Lead Time (days) | M1: Shelf Life (days) | N1: Min Order (pkgs) | O1: On Hand (units) | P1: Reorder Point (units) | Q1: Par Level (units) | R1: Used in # Items | S1: Units Used (sales log) | T1: Status | U1: Suggested Order (pkgs) | V1: Order Cost ($) | W1: Stock Value ($) | X1: Notes
A2: ING-001 | B2: Apple Juice | C2: Juice Base | D2: fl oz | E2: Valley Fresh Juices | F2: SKU-1007 | G2: 1 gal jug | H2: 128 | I2: 9.5 | J2: 1.2 | K2: =IFERROR((I2+J2)/H2,0) | L2: 3 | M2: 21 | N2: 2 | O2: 1640 | P2: 1024 | Q2: 3072 | R2: =COUNTIF(Recipes!$C$2:$C$1000,A2) | S2: =SUMIFS(Recipes!$J$2:$J$1000,Recipes!$C$2:$C$1000,A2) | T2: =IF(O2<=P2,"REORDER","OK") | U2: =IF(O2<=P2,MAX(N2,ROUNDUP(MAX(Q2-O2,0)/H2,0)),0) | V2: =U2*(I2+J2) | W2: =MAX(O2,0)*K2
A3: ING-002 | B3: Orange Juice | C3: Juice Base | D3: fl oz | E3: Valley Fresh Juices | F3: SKU-1014 | G3: 1 gal jug | H3: 128 | I3: 11.25 | J3: 1.2 | K3: =IFERROR((I3+J3)/H3,0) | L3: 3 | M3: 14 | N3: 2 | O3: 720 | P3: 1024 | Q3: 3072 | R3: =COUNTIF(Recipes!$C$2:$C$1000,A3) | S3: =SUMIFS(Recipes!$J$2:$J$1000,Recipes!$C$2:$C$1000,A3) | T3: =IF(O3<=P3,"REORDER","OK") | U3: =IF(O3<=P3,MAX(N3,ROUNDUP(MAX(Q3-O3,0)/H3,0)),0) | V3: =U3*(I3+J3) | W3: =MAX(O3,0)*K3
A4: ING-003 | B4: Pineapple Juice | C4: Juice Base | D4: fl oz | E4: Valley Fresh Juices | F4: SKU-1021 | G4: 46 fl oz can | H4: 46 | I4: 3.4 | J4: 0.4 | K4: =IFERROR((I4+J4)/H4,0) | L4: 3 | M4: 180 | N4: 6 | O4: 880 | P4: 552 | Q4: 1656 | R4: =COUNTIF(Recipes!$C$2:$C$1000,A4) | S4: =SUMIFS(Recipes!$J$2:$J$1000,Recipes!$C$2:$C$1000,A4) | T4: =IF(O4<=P4,"REORDER","OK") | U4: =IF(O4<=P4,MAX(N4,ROUNDUP(MAX(Q4-O4,0)/H4,0)),0) | V4: =U4*(I4+J4) | W4: =MAX(O4,0)*K4
A5: ING-004 | B5: Coconut Water | C5: Juice Base | D5: fl oz | E5: Island Imports | F5: SKU-1028 | G5: 1 L carton x 12 | H5: 405.6 | I5: 38 | J5: 6.5 | K5: =IFERROR((I5+J5)/H5,0) | L5: 7 | M5: 270 | N5: 1 | O5: 2400 | P5: 1600 | Q5: 4800 | R5: =COUNTIF(Recipes!$C$2:$C$1000,A5) | S5: =SUMIFS(Recipes!$J$2:$J$1000,Recipes!$C$2:$C$1000,A5) | T5: =IF(O5<=P5,"REORDER","OK") | U5: =IF(O5<=P5,MAX(N5,ROUNDUP(MAX(Q5-O5,0)/H5,0)),0) | V5: =U5*(I5+J5) | W5: =MAX(O5,0)*K5
A6: ING-005 | B6: Almond Milk | C6: Dairy & Alt | D6: fl oz | E6: Sysco | F6: SKU-1035 | G6: 64 fl oz carton x 6 | H6: 384 | I6: 21 | J6: 3 | K6: =IFERROR((I6+J6)/H6,0) | L6: 4 | M6: 60 | N6: 1 | O6: 1200 | P6: 1000 | Q6: 3072 | R6: =COUNTIF(Recipes!$C$2:$C$1000,A6) | S6: =SUMIFS(Recipes!$J$2:$J$1000,Recipes!$C$2:$C$1000,A6) | T6: =IF(O6<=P6,"REORDER","OK") | U6: =IF(O6<=P6,MAX(N6,ROUNDUP(MAX(Q6-O6,0)/H6,0)),0) | V6: =U6*(I6+J6) | W6: =MAX(O6,0)*K6
A7: ING-006 | B7: Greek Yogurt | C7: Dairy & Alt | D7: oz | E7: Sysco | F7: SKU-1042 | G7: 32 oz tub x 6 | H7: 192 | I7: 27 | J7: 3 | K7: =IFERROR((I7+J7)/H7,0) | L7: 4 | M7: 21 | N7: 1 | O7: 380 | P7: 480 | Q7: 1536 | R7: =COUNTIF(Recipes!$C$2:$C$1000,A7) | S7: =SUMIFS(Recipes!$J$2:$J$1000,Recipes!$C$2:$C$1000,A7) | T7: =IF(O7<=P7,"REORDER","OK") | U7: =IF(O7<=P7,MAX(N7,ROUNDUP(MAX(Q7-O7,0)/H7,0)),0) | V7: =U7*(I7+J7) | W7: =MAX(O7,0)*K7
A8: ING-007 | B8: Banana | C8: Fruit | D8: each | E8: GreenLeaf Produce | F8: SKU-1049 | G8: 40 lb case (~100 ct) | H8: 100 | I8: 28 | J8: 4 | K8: =IFERROR((I8+J8)/H8,0) | L8: 2 | M8: 6 | N8: 1 | O8: 256 | P8: 200 | Q8: 800 | R8: =COUNTIF(Recipes!$C$2:$C$1000,A8) | S8: =SUMIFS(Recipes!$J$2:$J$1000,Recipes!$C$2:$C$1000,A8) | T8: =IF(O8<=P8,"REORDER","OK") | U8: =IF(O8<=P8,MAX(N8,ROUNDUP(MAX(Q8-O8,0)/H8,0)),0) | V8: =U8*(I8+J8) | W8: =MAX(O8,0)*K8
A9: ING-008 | B9: Strawberries (frozen) | C9: Fruit | D9: oz | E9: Frosty Farms | F9: SKU-1056 | G9: 5 lb bag x 4 | H9: 320 | I9: 42 | J9: 8 | K9: =IFERROR((I9+J9)/H9,0) | L9: 5 | M9: 365 | N9: 1 | O9: 1640 | P9: 960 | Q9: 3840 | R9: =COUNTIF(Recipes!$C$2:$C$1000,A9) | S9: =SUMIFS(Recipes!$J$2:$J$1000,Recipes!$C$2:$C$1000,A9) | T9: =IF(O9<=P9,"REORDER","OK") | U9: =IF(O9<=P9,MAX(N9,ROUNDUP(MAX(Q9-O9,0)/H9,0)),0) | V9: =U9*(I9+J9) | W9: =MAX(O9,0)*K9
A10: ING-009 | B10: Mango (frozen) | C10: Fruit | D10: oz | E10: Frosty Farms | F10: SKU-1063 | G10: 5 lb bag x 4 | H10: 320 | I10: 46 | J10: 8 | K10: =IFERROR((I10+J10)/H10,0) | L10: 5 | M10: 365 | N10: 1 | O10: 600 | P10: 960 | Q10: 3840 | R10: =COUNTIF(Recipes!$C$2:$C$1000,A10) | S10: =SUMIFS(Recipes!$J$2:$J$1000,Recipes!$C$2:$C$1000,A10) | T10: =IF(O10<=P10,"REORDER","OK") | U10: =IF(O10<=P10,MAX(N10,ROUNDUP(MAX(Q10-O10,0)/H10,0)),0) | V10: =U10*(I10+J10) | W10: =MAX(O10,0)*K10
A11: ING-010 | B11: Peach (frozen) | C11: Fruit | D11: oz | E11: Frosty Farms | F11: SKU-1070 | G11: 5 lb bag x 4 | H11: 320 | I11: 44 | J11: 8 | K11: =IFERROR((I11+J11)/H11,0) | L11: 5 | M11: 365 | N11: 1 | O11: 2080 | P11: 960 | Q11: 3840 | R11: =COUNTIF(Recipes!$C$2:$C$1000,A11) | S11: =SUMIFS(Recipes!$J$2:$J$1000,Recipes!$C$2:$C$1000,A11) | T11: =IF(O11<=P11,"REORDER","OK") | U11: =IF(O11<=P11,MAX(N11,ROUNDUP(MAX(Q11-O11,0)/H11,0)),0) | V11: =U11*(I11+J11) | W11: =MAX(O11,0)*K11
A12: ING-011 | B12: Blueberries (frozen) | C12: Fruit | D12: oz | E12: Frosty Farms | F12: SKU-1077 | G12: 5 lb bag x 4 | H12: 320 | I12: 58 | J12: 8 | K12: =IFERROR((I12+J12)/H12,0) | L12: 5 | M12: 365 | N12: 1 | O12: 1560 | P12: 960 | Q12: 3840 | R12: =COUNTIF(Recipes!$C$2:$C$1000,A12) | S12: =SUMIFS(Recipes!$J$2:$J$1000,Recipes!$C$2:$C$1000,A12) | T12: =IF(O12<=P12,"REORDER","OK") | U12: =IF(O12<=P12,MAX(N12,ROUNDUP(MAX(Q12-O12,0)/H12,0)),0) | V12: =U12*(I12+J12) | W12: =MAX(O12,0)*K12
A13: ING-012 | B13: Pineapple Chunks | C13: Fruit | D13: oz | E13: GreenLeaf Produce | F13: SKU-1084 | G13: 10 lb case | H13: 160 | I13: 22 | J13: 3 | K13: =IFERROR((I13+J13)/H13,0) | L13: 2 | M13: 5 | N13: 1 | O13: 280 | P13: 256 | Q13: 960 | R13: =COUNTIF(Recipes!$C$2:$C$1000,A13) | S13: =SUMIFS(Recipes!$J$2:$J$1000,Recipes!$C$2:$C$1000,A13) | T13: =IF(O13<=P13,"REORDER","OK") | U13: =IF(O13<=P13,MAX(N13,ROUNDUP(MAX(Q13-O13,0)/H13,0)),0) | V13: =U13*(I13+J13) | W13: =MAX(O13,0)*K13
... A32: ING-031 | B32: 24 oz Cup + Lid + Straw | C32: Packaging | D32: each | E32: EcoServe Packaging | F32: SKU-1217 | G32: Case of 400 | H32: 400 | I32: 92 | J32: 12 | K32: =IFERROR((I32+J32)/H32,0) | L32: 6 | M32: 0 | N32: 1 | O32: 560 | P32: 800 | Q32: 3200 | R32: =COUNTIF(Recipes!$C$2:$C$1000,A32) | S32: =SUMIFS(Recipes!$J$2:$J$1000,Recipes!$C$2:$C$1000,A32) | T32: =IF(O32<=P32,"REORDER","OK") | U32: =IF(O32<=P32,MAX(N32,ROUNDUP(MAX(Q32-O32,0)/H32,0)),0) | V32: =U32*(I32+J32) | W32: =MAX(O32,0)*K32

Sheet Menu Items
A1: Item ID | B1: Name | C1: Category | D1: Size | E1: Price ($) | F1: Description | G1: Image File | H1: Active | I1: # Ingredients | J1: Ingredient Cost ($) | K1: Gross Margin ($) | L1: Cost % | M1: Units Sold | N1: Revenue ($)
A2: MI-001 | B2: Green Machine | C2: Cold-Pressed Juice | D2: 16 oz | E2: 8.95 | F2: Spinach, kale, cucumber, celery, apple and a squeeze of lemon. Our best-selling daily green. | H2: Yes | I2: =COUNTIF(Recipes!$A$2:$A$1000,A2) | J2: =SUMIFS(Recipes!$H$2:$H$1000,Recipes!$A$2:$A$1000,A2) | K2: =E2-J2 | L2: =IFERROR(J2/E2,0) | M2: =SUMIFS('Sales Log'!$C$2:$C$2000,'Sales Log'!$B$2:$B$2000,A2) | N2: =M2*E2
A3: MI-002 | B3: Sunrise Carrot | C3: Cold-Pressed Juice | D3: 16 oz | E3: 7.95 | F3: Carrot, orange, ginger and turmeric. Bright, zesty and anti-inflammatory. | H3: Yes | I3: =COUNTIF(Recipes!$A$2:$A$1000,A3) | J3: =SUMIFS(Recipes!$H$2:$H$1000,Recipes!$A$2:$A$1000,A3) | K3: =E3-J3 | L3: =IFERROR(J3/E3,0) | M3: =SUMIFS('Sales Log'!$C$2:$C$2000,'Sales Log'!$B$2:$B$2000,A3) | N3: =M3*E3
A4: MI-003 | B4: Beet Boost | C4: Cold-Pressed Juice | D4: 16 oz | E4: 8.5 | F4: Beet, carrot, apple, lemon and ginger. Earthy, sweet and energizing. | H4: Yes | I4: =COUNTIF(Recipes!$A$2:$A$1000,A4) | J4: =SUMIFS(Recipes!$H$2:$H$1000,Recipes!$A$2:$A$1000,A4) | K4: =E4-J4 | L4: =IFERROR(J4/E4,0) | M4: =SUMIFS('Sales Log'!$C$2:$C$2000,'Sales Log'!$B$2:$B$2000,A4) | N4: =M4*E4
A5: MI-004 | B5: Ginger Shot | C5: Wellness Shot | D5: 2 oz | E5: 3.5 | F5: A fiery 2 oz shot of ginger, lemon and a touch of honey. | H5: Yes | I5: =COUNTIF(Recipes!$A$2:$A$1000,A5) | J5: =SUMIFS(Recipes!$H$2:$H$1000,Recipes!$A$2:$A$1000,A5) | K5: =E5-J5 | L5: =IFERROR(J5/E5,0) | M5: =SUMIFS('Sales Log'!$C$2:$C$2000,'Sales Log'!$B$2:$B$2000,A5) | N5: =M5*E5
A6: MI-005 | B6: Peach Paradise | C6: Smoothie | D6: 24 oz | E6: 8.95 | F6: Peach, mango, banana, Greek yogurt and apple juice blended creamy. | H6: Yes | I6: =COUNTIF(Recipes!$A$2:$A$1000,A6) | J6: =SUMIFS(Recipes!$H$2:$H$1000,Recipes!$A$2:$A$1000,A6) | K6: =E6-J6 | L6: =IFERROR(J6/E6,0) | M6: =SUMIFS('Sales Log'!$C$2:$C$2000,'Sales Log'!$B$2:$B$2000,A6) | N6: =M6*E6
A7: MI-006 | B7: Strawberry Banana | C7: Smoothie | D7: 24 oz | E7: 7.95 | F7: The classic: strawberries, banana, Greek yogurt, apple juice and honey. | H7: Yes | I7: =COUNTIF(Recipes!$A$2:$A$1000,A7) | J7: =SUMIFS(Recipes!$H$2:$H$1000,Recipes!$A$2:$A$1000,A7) | K7: =E7-J7 | L7: =IFERROR(J7/E7,0) | M7: =SUMIFS('Sales Log'!$C$2:$C$2000,'Sales Log'!$B$2:$B$2000,A7) | N7: =M7*E7
A8: MI-007 | B8: Tropical Escape | C8: Smoothie | D8: 24 oz | E8: 8.5 | F8: Pineapple, mango, banana and coconut water. Dairy-free vacation in a cup. | H8: Yes | I8: =COUNTIF(Recipes!$A$2:$A$1000,A8) | J8: =SUMIFS(Recipes!$H$2:$H$1000,Recipes!$A$2:$A$1000,A8) | K8: =E8-J8 | L8: =IFERROR(J8/E8,0) | M8: =SUMIFS('Sales Log'!$C$2:$C$2000,'Sales Log'!$B$2:$B$2000,A8) | N8: =M8*E8
A9: MI-008 | B9: Berry Blast | C9: Smoothie | D9: 24 oz | E9: 8.5 | F9: Blueberries, strawberries, banana, almond milk and chia seeds. | H9: Yes | I9: =COUNTIF(Recipes!$A$2:$A$1000,A9) | J9: =SUMIFS(Recipes!$H$2:$H$1000,Recipes!$A$2:$A$1000,A9) | K9: =E9-J9 | L9: =IFERROR(J9/E9,0) | M9: =SUMIFS('Sales Log'!$C$2:$C$2000,'Sales Log'!$B$2:$B$2000,A9) | N9: =M9*E9
A10: MI-009 | B10: PB Power | C10: Protein Smoothie | D10: 24 oz | E10: 9.95 | F10: Peanut butter, banana, whey protein and almond milk. 30 g of protein. | H10: Yes | I10: =COUNTIF(Recipes!$A$2:$A$1000,A10) | J10: =SUMIFS(Recipes!$H$2:$H$1000,Recipes!$A$2:$A$1000,A10) | K10: =E10-J10 | L10: =IFERROR(J10/E10,0) | M10: =SUMIFS('Sales Log'!$C$2:$C$2000,'Sales Log'!$B$2:$B$2000,A10) | N10: =M10*E10
A11: MI-010 | B11: Green Protein | C11: Protein Smoothie | D11: 24 oz | E11: 10.5 | F11: Spinach, banana, mango, whey protein and almond milk. | H11: Yes | I11: =COUNTIF(Recipes!$A$2:$A$1000,A11) | J11: =SUMIFS(Recipes!$H$2:$H$1000,Recipes!$A$2:$A$1000,A11) | K11: =E11-J11 | L11: =IFERROR(J11/E11,0) | M11: =SUMIFS('Sales Log'!$C$2:$C$2000,'Sales Log'!$B$2:$B$2000,A11) | N11: =M11*E11
A12: MI-011 | B12: Mint Lemonade | C12: Refresher | D12: 16 oz | E12: 5.5 | F12: Fresh lemon, mint and agave over ice. | H12: Yes | I12: =COUNTIF(Recipes!$A$2:$A$1000,A12) | J12: =SUMIFS(Recipes!$H$2:$H$1000,Recipes!$A$2:$A$1000,A12) | K12: =E12-J12 | L12: =IFERROR(J12/E12,0) | M12: =SUMIFS('Sales Log'!$C$2:$C$2000,'Sales Log'!$B$2:$B$2000,A12) | N12: =M12*E12
A13: MI-012 | B13: Acai Energy | C13: Smoothie | D13: 24 oz | E13: 10.95 | F13: Acai, blueberries, banana, apple juice and honey. | H13: Yes | I13: =COUNTIF(Recipes!$A$2:$A$1000,A13) | J13: =SUMIFS(Recipes!$H$2:$H$1000,Recipes!$A$2:$A$1000,A13) | K13: =E13-J13 | L13: =IFERROR(J13/E13,0) | M13: =SUMIFS('Sales Log'!$C$2:$C$2000,'Sales Log'!$B$2:$B$2000,A13) | N13: =M13*E13

Sheet Recipes
A1: Item ID | B1: Item Name | C1: Ingredient ID | D1: Ingredient Name | E1: Qty per Item | F1: Unit | G1: Unit Cost ($) | H1: Line Cost ($) | I1: Item Units Sold | J1: Ingredient Used
A2: MI-001 | B2: =IFERROR(INDEX('Menu Items'!$B$2:$B$200,MATCH(A2,'Menu Items'!$A$2:$A$200,0)),"") | C2: ING-014 | D2: =IFERROR(INDEX(Ingredients!$B$2:$B$200,MATCH(C2,Ingredients!$A$2:$A$200,0)),"") | E2: 2 | F2: =IFERROR(INDEX(Ingredients!$D$2:$D$200,MATCH(C2,Ingredients!$A$2:$A$200,0)),"") | G2: =IFERROR(INDEX(Ingredients!$K$2:$K$200,MATCH(C2,Ingredients!$A$2:$A$200,0)),0) | H2: =IFERROR(E2*G2,0) | I2: =IFERROR(INDEX('Menu Items'!$M$2:$M$200,MATCH(A2,'Menu Items'!$A$2:$A$200,0)),0) | J2: =IFERROR(E2*I2,0)
A3: MI-001 | B3: =IFERROR(INDEX('Menu Items'!$B$2:$B$200,MATCH(A3,'Menu Items'!$A$2:$A$200,0)),"") | C3: ING-015 | D3: =IFERROR(INDEX(Ingredients!$B$2:$B$200,MATCH(C3,Ingredients!$A$2:$A$200,0)),"") | E3: 2 | F3: =IFERROR(INDEX(Ingredients!$D$2:$D$200,MATCH(C3,Ingredients!$A$2:$A$200,0)),"") | G3: =IFERROR(INDEX(Ingredients!$K$2:$K$200,MATCH(C3,Ingredients!$A$2:$A$200,0)),0) | H3: =IFERROR(E3*G3,0) | I3: =IFERROR(INDEX('Menu Items'!$M$2:$M$200,MATCH(A3,'Menu Items'!$A$2:$A$200,0)),0) | J3: =IFERROR(E3*I3,0)
A4: MI-001 | B4: =IFERROR(INDEX('Menu Items'!$B$2:$B$200,MATCH(A4,'Menu Items'!$A$2:$A$200,0)),"") | C4: ING-016 | D4: =IFERROR(INDEX(Ingredients!$B$2:$B$200,MATCH(C4,Ingredients!$A$2:$A$200,0)),"") | E4: 1 | F4: =IFERROR(INDEX(Ingredients!$D$2:$D$200,MATCH(C4,Ingredients!$A$2:$A$200,0)),"") | G4: =IFERROR(INDEX(Ingredients!$K$2:$K$200,MATCH(C4,Ingredients!$A$2:$A$200,0)),0) | H4: =IFERROR(E4*G4,0) | I4: =IFERROR(INDEX('Menu Items'!$M$2:$M$200,MATCH(A4,'Menu Items'!$A$2:$A$200,0)),0) | J4: =IFERROR(E4*I4,0)
A5: MI-001 | B5: =IFERROR(INDEX('Menu Items'!$B$2:$B$200,MATCH(A5,'Menu Items'!$A$2:$A$200,0)),"") | C5: ING-017 | D5: =IFERROR(INDEX(Ingredients!$B$2:$B$200,MATCH(C5,Ingredients!$A$2:$A$200,0)),"") | E5: 4 | F5: =IFERROR(INDEX(Ingredients!$D$2:$D$200,MATCH(C5,Ingredients!$A$2:$A$200,0)),"") | G5: =IFERROR(INDEX(Ingredients!$K$2:$K$200,MATCH(C5,Ingredients!$A$2:$A$200,0)),0) | H5: =IFERROR(E5*G5,0) | I5: =IFERROR(INDEX('Menu Items'!$M$2:$M$200,MATCH(A5,'Menu Items'!$A$2:$A$200,0)),0) | J5: =IFERROR(E5*I5,0)
A6: MI-001 | B6: =IFERROR(INDEX('Menu Items'!$B$2:$B$200,MATCH(A6,'Menu Items'!$A$2:$A$200,0)),"") | C6: ING-001 | D6: =IFERROR(INDEX(Ingredients!$B$2:$B$200,MATCH(C6,Ingredients!$A$2:$A$200,0)),"") | E6: 6 | F6: =IFERROR(INDEX(Ingredients!$D$2:$D$200,MATCH(C6,Ingredients!$A$2:$A$200,0)),"") | G6: =IFERROR(INDEX(Ingredients!$K$2:$K$200,MATCH(C6,Ingredients!$A$2:$A$200,0)),0) | H6: =IFERROR(E6*G6,0) | I6: =IFERROR(INDEX('Menu Items'!$M$2:$M$200,MATCH(A6,'Menu Items'!$A$2:$A$200,0)),0) | J6: =IFERROR(E6*I6,0)
A7: MI-001 | B7: =IFERROR(INDEX('Menu Items'!$B$2:$B$200,MATCH(A7,'Menu Items'!$A$2:$A$200,0)),"") | C7: ING-013 | D7: =IFERROR(INDEX(Ingredients!$B$2:$B$200,MATCH(C7,Ingredients!$A$2:$A$200,0)),"") | E7: 0.5 | F7: =IFERROR(INDEX(Ingredients!$D$2:$D$200,MATCH(C7,Ingredients!$A$2:$A$200,0)),"") | G7: =IFERROR(INDEX(Ingredients!$K$2:$K$200,MATCH(C7,Ingredients!$A$2:$A$200,0)),0) | H7: =IFERROR(E7*G7,0) | I7: =IFERROR(INDEX('Menu Items'!$M$2:$M$200,MATCH(A7,'Menu Items'!$A$2:$A$200,0)),0) | J7: =IFERROR(E7*I7,0)
A8: MI-001 | B8: =IFERROR(INDEX('Menu Items'!$B$2:$B$200,MATCH(A8,'Menu Items'!$A$2:$A$200,0)),"") | C8: ING-030 | D8: =IFERROR(INDEX(Ingredients!$B$2:$B$200,MATCH(C8,Ingredients!$A$2:$A$200,0)),"") | E8: 1 | F8: =IFERROR(INDEX(Ingredients!$D$2:$D$200,MATCH(C8,Ingredients!$A$2:$A$200,0)),"") | G8: =IFERROR(INDEX(Ingredients!$K$2:$K$200,MATCH(C8,Ingredients!$A$2:$A$200,0)),0) | H8: =IFERROR(E8*G8,0) | I8: =IFERROR(INDEX('Menu Items'!$M$2:$M$200,MATCH(A8,'Menu Items'!$A$2:$A$200,0)),0) | J8: =IFERROR(E8*I8,0)
A9: MI-002 | B9: =IFERROR(INDEX('Menu Items'!$B$2:$B$200,MATCH(A9,'Menu Items'!$A$2:$A$200,0)),"") | C9: ING-018 | D9: =IFERROR(INDEX(Ingredients!$B$2:$B$200,MATCH(C9,Ingredients!$A$2:$A$200,0)),"") | E9: 10 | F9: =IFERROR(INDEX(Ingredients!$D$2:$D$200,MATCH(C9,Ingredients!$A$2:$A$200,0)),"") | G9: =IFERROR(INDEX(Ingredients!$K$2:$K$200,MATCH(C9,Ingredients!$A$2:$A$200,0)),0) | H9: =IFERROR(E9*G9,0) | I9: =IFERROR(INDEX('Menu Items'!$M$2:$M$200,MATCH(A9,'Menu Items'!$A$2:$A$200,0)),0) | J9: =IFERROR(E9*I9,0)
A10: MI-002 | B10: =IFERROR(INDEX('Menu Items'!$B$2:$B$200,MATCH(A10,'Menu Items'!$A$2:$A$200,0)),"") | C10: ING-002 | D10: =IFERROR(INDEX(Ingredients!$B$2:$B$200,MATCH(C10,Ingredients!$A$2:$A$200,0)),"") | E10: 6 | F10: =IFERROR(INDEX(Ingredients!$D$2:$D$200,MATCH(C10,Ingredients!$A$2:$A$200,0)),"") | G10: =IFERROR(INDEX(Ingredients!$K$2:$K$200,MATCH(C10,Ingredients!$A$2:$A$200,0)),0) | H10: =IFERROR(E10*G10,0) | I10: =IFERROR(INDEX('Menu Items'!$M$2:$M$200,MATCH(A10,'Menu Items'!$A$2:$A$200,0)),0) | J10: =IFERROR(E10*I10,0)
A11: MI-002 | B11: =IFERROR(INDEX('Menu Items'!$B$2:$B$200,MATCH(A11,'Menu Items'!$A$2:$A$200,0)),"") | C11: ING-020 | D11: =IFERROR(INDEX(Ingredients!$B$2:$B$200,MATCH(C11,Ingredients!$A$2:$A$200,0)),"") | E11: 0.5 | F11: =IFERROR(INDEX(Ingredients!$D$2:$D$200,MATCH(C11,Ingredients!$A$2:$A$200,0)),"") | G11: =IFERROR(INDEX(Ingredients!$K$2:$K$200,MATCH(C11,Ingredients!$A$2:$A$200,0)),0) | H11: =IFERROR(E11*G11,0) | I11: =IFERROR(INDEX('Menu Items'!$M$2:$M$200,MATCH(A11,'Menu Items'!$A$2:$A$200,0)),0) | J11: =IFERROR(E11*I11,0)
A12: MI-002 | B12: =IFERROR(INDEX('Menu Items'!$B$2:$B$200,MATCH(A12,'Menu Items'!$A$2:$A$200,0)),"") | C12: ING-021 | D12: =IFERROR(INDEX(Ingredients!$B$2:$B$200,MATCH(C12,Ingredients!$A$2:$A$200,0)),"") | E12: 0.25 | F12: =IFERROR(INDEX(Ingredients!$D$2:$D$200,MATCH(C12,Ingredients!$A$2:$A$200,0)),"") | G12: =IFERROR(INDEX(Ingredients!$K$2:$K$200,MATCH(C12,Ingredients!$A$2:$A$200,0)),0) | H12: =IFERROR(E12*G12,0) | I12: =IFERROR(INDEX('Menu Items'!$M$2:$M$200,MATCH(A12,'Menu Items'!$A$2:$A$200,0)),0) | J12: =IFERROR(E12*I12,0)
A13: MI-002 | B13: =IFERROR(INDEX('Menu Items'!$B$2:$B$200,MATCH(A13,'Menu Items'!$A$2:$A$200,0)),"") | C13: ING-030 | D13: =IFERROR(INDEX(Ingredients!$B$2:$B$200,MATCH(C13,Ingredients!$A$2:$A$200,0)),"") | E13: 1 | F13: =IFERROR(INDEX(Ingredients!$D$2:$D$200,MATCH(C13,Ingredients!$A$2:$A$200,0)),"") | G13: =IFERROR(INDEX(Ingredients!$K$2:$K$200,MATCH(C13,Ingredients!$A$2:$A$200,0)),0) | H13: =IFERROR(E13*G13,0) | I13: =IFERROR(INDEX('Menu Items'!$M$2:$M$200,MATCH(A13,'Menu Items'!$A$2:$A$200,0)),0) | J13: =IFERROR(E13*I13,0)
... A75: MI-012 | B75: =IFERROR(INDEX('Menu Items'!$B$2:$B$200,MATCH(A75,'Menu Items'!$A$2:$A$200,0)),"") | C75: ING-031 | D75: =IFERROR(INDEX(Ingredients!$B$2:$B$200,MATCH(C75,Ingredients!$A$2:$A$200,0)),"") | E75: 1 | F75: =IFERROR(INDEX(Ingredients!$D$2:$D$200,MATCH(C75,Ingredients!$A$2:$A$200,0)),"") | G75: =IFERROR(INDEX(Ingredients!$K$2:$K$200,MATCH(C75,Ingredients!$A$2:$A$200,0)),0) | H75: =IFERROR(E75*G75,0) | I75: =IFERROR(INDEX('Menu Items'!$M$2:$M$200,MATCH(A75,'Menu Items'!$A$2:$A$200,0)),0) | J75: =IFERROR(E75*I75,0)

Sheet Where Used
A1: Ingredient | B1: Ingredient ID | C1: Unit | D1: =IFERROR(INDEX('Menu Items'!$B$2:$B$200,MATCH(D$2,'Menu Items'!$A$2:$A$200,0)),"") | E1: =IFERROR(INDEX('Menu Items'!$B$2:$B$200,MATCH(E$2,'Menu Items'!$A$2:$A$200,0)),"") | F1: =IFERROR(INDEX('Menu Items'!$B$2:$B$200,MATCH(F$2,'Menu Items'!$A$2:$A$200,0)),"") | G1: =IFERROR(INDEX('Menu Items'!$B$2:$B$200,MATCH(G$2,'Menu Items'!$A$2:$A$200,0)),"") | H1: =IFERROR(INDEX('Menu Items'!$B$2:$B$200,MATCH(H$2,'Menu Items'!$A$2:$A$200,0)),"") | I1: =IFERROR(INDEX('Menu Items'!$B$2:$B$200,MATCH(I$2,'Menu Items'!$A$2:$A$200,0)),"") | J1: =IFERROR(INDEX('Menu Items'!$B$2:$B$200,MATCH(J$2,'Menu Items'!$A$2:$A$200,0)),"") | K1: =IFERROR(INDEX('Menu Items'!$B$2:$B$200,MATCH(K$2,'Menu Items'!$A$2:$A$200,0)),"") | ... O1: =IFERROR(INDEX('Menu Items'!$B$2:$B$200,MATCH(O$2,'Menu Items'!$A$2:$A$200,0)),"")
A2: Quantity of each ingredient per menu item (blank = not used) | D2: MI-001 | E2: MI-002 | F2: MI-003 | G2: MI-004 | H2: MI-005 | I2: MI-006 | J2: MI-007 | K2: MI-008 | L2: MI-009 | M2: MI-010 | N2: MI-011 | O2: MI-012
A3: =IFERROR(INDEX(Ingredients!$B$2:$B$200,MATCH($B3,Ingredients!$A$2:$A$200,0)),"") | B3: ING-001 | C3: =IFERROR(INDEX(Ingredients!$D$2:$D$200,MATCH($B3,Ingredients!$A$2:$A$200,0)),"") | D3: =SUMIFS(Recipes!$E$2:$E$1000,Recipes!$A$2:$A$1000,D$2,Recipes!$C$2:$C$1000,$B3) | E3: =SUMIFS(Recipes!$E$2:$E$1000,Recipes!$A$2:$A$1000,E$2,Recipes!$C$2:$C$1000,$B3) | F3: =SUMIFS(Recipes!$E$2:$E$1000,Recipes!$A$2:$A$1000,F$2,Recipes!$C$2:$C$1000,$B3) | G3: =SUMIFS(Recipes!$E$2:$E$1000,Recipes!$A$2:$A$1000,G$2,Recipes!$C$2:$C$1000,$B3) | H3: =SUMIFS(Recipes!$E$2:$E$1000,Recipes!$A$2:$A$1000,H$2,Recipes!$C$2:$C$1000,$B3) | I3: =SUMIFS(Recipes!$E$2:$E$1000,Recipes!$A$2:$A$1000,I$2,Recipes!$C$2:$C$1000,$B3) | J3: =SUMIFS(Recipes!$E$2:$E$1000,Recipes!$A$2:$A$1000,J$2,Recipes!$C$2:$C$1000,$B3) | K3: =SUMIFS(Recipes!$E$2:$E$1000,Recipes!$A$2:$A$1000,K$2,Recipes!$C$2:$C$1000,$B3) | ... O3: =SUMIFS(Recipes!$E$2:$E$1000,Recipes!$A$2:$A$1000,O$2,Recipes!$C$2:$C$1000,$B3)
A4: =IFERROR(INDEX(Ingredients!$B$2:$B$200,MATCH($B4,Ingredients!$A$2:$A$200,0)),"") | B4: ING-002 | C4: =IFERROR(INDEX(Ingredients!$D$2:$D$200,MATCH($B4,Ingredients!$A$2:$A$200,0)),"") | D4: =SUMIFS(Recipes!$E$2:$E$1000,Recipes!$A$2:$A$1000,D$2,Recipes!$C$2:$C$1000,$B4) | E4: =SUMIFS(Recipes!$E$2:$E$1000,Recipes!$A$2:$A$1000,E$2,Recipes!$C$2:$C$1000,$B4) | F4: =SUMIFS(Recipes!$E$2:$E$1000,Recipes!$A$2:$A$1000,F$2,Recipes!$C$2:$C$1000,$B4) | G4: =SUMIFS(Recipes!$E$2:$E$1000,Recipes!$A$2:$A$1000,G$2,Recipes!$C$2:$C$1000,$B4) | H4: =SUMIFS(Recipes!$E$2:$E$1000,Recipes!$A$2:$A$1000,H$2,Recipes!$C$2:$C$1000,$B4) | I4: =SUMIFS(Recipes!$E$2:$E$1000,Recipes!$A$2:$A$1000,I$2,Recipes!$C$2:$C$1000,$B4) | J4: =SUMIFS(Recipes!$E$2:$E$1000,Recipes!$A$2:$A$1000,J$2,Recipes!$C$2:$C$1000,$B4) | K4: =SUMIFS(Recipes!$E$2:$E$1000,Recipes!$A$2:$A$1000,K$2,Recipes!$C$2:$C$1000,$B4) | ... O4: =SUMIFS(Recipes!$E$2:$E$1000,Recipes!$A$2:$A$1000,O$2,Recipes!$C$2:$C$1000,$B4)
A5: =IFERROR(INDEX(Ingredients!$B$2:$B$200,MATCH($B5,Ingredients!$A$2:$A$200,0)),"") | B5: ING-003 | C5: =IFERROR(INDEX(Ingredients!$D$2:$D$200,MATCH($B5,Ingredients!$A$2:$A$200,0)),"") | D5: =SUMIFS(Recipes!$E$2:$E$1000,Recipes!$A$2:$A$1000,D$2,Recipes!$C$2:$C$1000,$B5) | E5: =SUMIFS(Recipes!$E$2:$E$1000,Recipes!$A$2:$A$1000,E$2,Recipes!$C$2:$C$1000,$B5) | F5: =SUMIFS(Recipes!$E$2:$E$1000,Recipes!$A$2:$A$1000,F$2,Recipes!$C$2:$C$1000,$B5) | G5: =SUMIFS(Recipes!$E$2:$E$1000,Recipes!$A$2:$A$1000,G$2,Recipes!$C$2:$C$1000,$B5) | H5: =SUMIFS(Recipes!$E$2:$E$1000,Recipes!$A$2:$A$1000,H$2,Recipes!$C$2:$C$1000,$B5) | I5: =SUMIFS(Recipes!$E$2:$E$1000,Recipes!$A$2:$A$1000,I$2,Recipes!$C$2:$C$1000,$B5) | J5: =SUMIFS(Recipes!$E$2:$E$1000,Recipes!$A$2:$A$1000,J$2,Recipes!$C$2:$C$1000,$B5) | K5: =SUMIFS(Recipes!$E$2:$E$1000,Recipes!$A$2:$A$1000,K$2,Recipes!$C$2:$C$1000,$B5) | ... O5: =SUMIFS(Recipes!$E$2:$E$1000,Recipes!$A$2:$A$1000,O$2,Recipes!$C$2:$C$1000,$B5)
A6: =IFERROR(INDEX(Ingredients!$B$2:$B$200,MATCH($B6,Ingredients!$A$2:$A$200,0)),"") | B6: ING-004 | C6: =IFERROR(INDEX(Ingredients!$D$2:$D$200,MATCH($B6,Ingredients!$A$2:$A$200,0)),"") | D6: =SUMIFS(Recipes!$E$2:$E$1000,Recipes!$A$2:$A$1000,D$2,Recipes!$C$2:$C$1000,$B6) | E6: =SUMIFS(Recipes!$E$2:$E$1000,Recipes!$A$2:$A$1000,E$2,Recipes!$C$2:$C$1000,$B6) | F6: =SUMIFS(Recipes!$E$2:$E$1000,Recipes!$A$2:$A$1000,F$2,Recipes!$C$2:$C$1000,$B6) | G6: =SUMIFS(Recipes!$E$2:$E$1000,Recipes!$A$2:$A$1000,G$2,Recipes!$C$2:$C$1000,$B6) | H6: =SUMIFS(Recipes!$E$2:$E$1000,Recipes!$A$2:$A$1000,H$2,Recipes!$C$2:$C$1000,$B6) | I6: =SUMIFS(Recipes!$E$2:$E$1000,Recipes!$A$2:$A$1000,I$2,Recipes!$C$2:$C$1000,$B6) | J6: =SUMIFS(Recipes!$E$2:$E$1000,Recipes!$A$2:$A$1000,J$2,Recipes!$C$2:$C$1000,$B6) | K6: =SUMIFS(Recipes!$E$2:$E$1000,Recipes!$A$2:$A$1000,K$2,Recipes!$C$2:$C$1000,$B6) | ... O6: =SUMIFS(Recipes!$E$2:$E$1000,Recipes!$A$2:$A$1000,O$2,Recipes!$C$2:$C$1000,$B6)
A7: =IFERROR(INDEX(Ingredients!$B$2:$B$200,MATCH($B7,Ingredients!$A$2:$A$200,0)),"") | B7: ING-005 | C7: =IFERROR(INDEX(Ingredients!$D$2:$D$200,MATCH($B7,Ingredients!$A$2:$A$200,0)),"") | D7: =SUMIFS(Recipes!$E$2:$E$1000,Recipes!$A$2:$A$1000,D$2,Recipes!$C$2:$C$1000,$B7) | E7: =SUMIFS(Recipes!$E$2:$E$1000,Recipes!$A$2:$A$1000,E$2,Recipes!$C$2:$C$1000,$B7) | F7: =SUMIFS(Recipes!$E$2:$E$1000,Recipes!$A$2:$A$1000,F$2,Recipes!$C$2:$C$1000,$B7) | G7: =SUMIFS(Recipes!$E$2:$E$1000,Recipes!$A$2:$A$1000,G$2,Recipes!$C$2:$C$1000,$B7) | H7: =SUMIFS(Recipes!$E$2:$E$1000,Recipes!$A$2:$A$1000,H$2,Recipes!$C$2:$C$1000,$B7) | I7: =SUMIFS(Recipes!$E$2:$E$1000,Recipes!$A$2:$A$1000,I$2,Recipes!$C$2:$C$1000,$B7) | J7: =SUMIFS(Recipes!$E$2:$E$1000,Recipes!$A$2:$A$1000,J$2,Recipes!$C$2:$C$1000,$B7) | K7: =SUMIFS(Recipes!$E$2:$E$1000,Recipes!$A$2:$A$1000,K$2,Recipes!$C$2:$C$1000,$B7) | ... O7: =SUMIFS(Recipes!$E$2:$E$1000,Recipes!$A$2:$A$1000,O$2,Recipes!$C$2:$C$1000,$B7)
A8: =IFERROR(INDEX(Ingredients!$B$2:$B$200,MATCH($B8,Ingredients!$A$2:$A$200,0)),"") | B8: ING-006 | C8: =IFERROR(INDEX(Ingredients!$D$2:$D$200,MATCH($B8,Ingredients!$A$2:$A$200,0)),"") | D8: =SUMIFS(Recipes!$E$2:$E$1000,Recipes!$A$2:$A$1000,D$2,Recipes!$C$2:$C$1000,$B8) | E8: =SUMIFS(Recipes!$E$2:$E$1000,Recipes!$A$2:$A$1000,E$2,Recipes!$C$2:$C$1000,$B8) | F8: =SUMIFS(Recipes!$E$2:$E$1000,Recipes!$A$2:$A$1000,F$2,Recipes!$C$2:$C$1000,$B8) | G8: =SUMIFS(Recipes!$E$2:$E$1000,Recipes!$A$2:$A$1000,G$2,Recipes!$C$2:$C$1000,$B8) | H8: =SUMIFS(Recipes!$E$2:$E$1000,Recipes!$A$2:$A$1000,H$2,Recipes!$C$2:$C$1000,$B8) | I8: =SUMIFS(Recipes!$E$2:$E$1000,Recipes!$A$2:$A$1000,I$2,Recipes!$C$2:$C$1000,$B8) | J8: =SUMIFS(Recipes!$E$2:$E$1000,Recipes!$A$2:$A$1000,J$2,Recipes!$C$2:$C$1000,$B8) | K8: =SUMIFS(Recipes!$E$2:$E$1000,Recipes!$A$2:$A$1000,K$2,Recipes!$C$2:$C$1000,$B8) | ... O8: =SUMIFS(Recipes!$E$2:$E$1000,Recipes!$A$2:$A$1000,O$2,Recipes!$C$2:$C$1000,$B8)
A9: =IFERROR(INDEX(Ingredients!$B$2:$B$200,MATCH($B9,Ingredients!$A$2:$A$200,0)),"") | B9: ING-007 | C9: =IFERROR(INDEX(Ingredients!$D$2:$D$200,MATCH($B9,Ingredients!$A$2:$A$200,0)),"") | D9: =SUMIFS(Recipes!$E$2:$E$1000,Recipes!$A$2:$A$1000,D$2,Recipes!$C$2:$C$1000,$B9) | E9: =SUMIFS(Recipes!$E$2:$E$1000,Recipes!$A$2:$A$1000,E$2,Recipes!$C$2:$C$1000,$B9) | F9: =SUMIFS(Recipes!$E$2:$E$1000,Recipes!$A$2:$A$1000,F$2,Recipes!$C$2:$C$1000,$B9) | G9: =SUMIFS(Recipes!$E$2:$E$1000,Recipes!$A$2:$A$1000,G$2,Recipes!$C$2:$C$1000,$B9) | H9: =SUMIFS(Recipes!$E$2:$E$1000,Recipes!$A$2:$A$1000,H$2,Recipes!$C$2:$C$1000,$B9) | I9: =SUMIFS(Recipes!$E$2:$E$1000,Recipes!$A$2:$A$1000,I$2,Recipes!$C$2:$C$1000,$B9) | J9: =SUMIFS(Recipes!$E$2:$E$1000,Recipes!$A$2:$A$1000,J$2,Recipes!$C$2:$C$1000,$B9) | K9: =SUMIFS(Recipes!$E$2:$E$1000,Recipes!$A$2:$A$1000,K$2,Recipes!$C$2:$C$1000,$B9) | ... O9: =SUMIFS(Recipes!$E$2:$E$1000,Recipes!$A$2:$A$1000,O$2,Recipes!$C$2:$C$1000,$B9)
A10: =IFERROR(INDEX(Ingredients!$B$2:$B$200,MATCH($B10,Ingredients!$A$2:$A$200,0)),"") | B10: ING-008 | C10: =IFERROR(INDEX(Ingredients!$D$2:$D$200,MATCH($B10,Ingredients!$A$2:$A$200,0)),"") | D10: =SUMIFS(Recipes!$E$2:$E$1000,Recipes!$A$2:$A$1000,D$2,Recipes!$C$2:$C$1000,$B10) | E10: =SUMIFS(Recipes!$E$2:$E$1000,Recipes!$A$2:$A$1000,E$2,Recipes!$C$2:$C$1000,$B10) | F10: =SUMIFS(Recipes!$E$2:$E$1000,Recipes!$A$2:$A$1000,F$2,Recipes!$C$2:$C$1000,$B10) | G10: =SUMIFS(Recipes!$E$2:$E$1000,Recipes!$A$2:$A$1000,G$2,Recipes!$C$2:$C$1000,$B10) | H10: =SUMIFS(Recipes!$E$2:$E$1000,Recipes!$A$2:$A$1000,H$2,Recipes!$C$2:$C$1000,$B10) | I10: =SUMIFS(Recipes!$E$2:$E$1000,Recipes!$A$2:$A$1000,I$2,Recipes!$C$2:$C$1000,$B10) | J10: =SUMIFS(Recipes!$E$2:$E$1000,Recipes!$A$2:$A$1000,J$2,Recipes!$C$2:$C$1000,$B10) | K10: =SUMIFS(Recipes!$E$2:$E$1000,Recipes!$A$2:$A$1000,K$2,Recipes!$C$2:$C$1000,$B10) | ... O10: =SUMIFS(Recipes!$E$2:$E$1000,Recipes!$A$2:$A$1000,O$2,Recipes!$C$2:$C$1000,$B10)
A11: =IFERROR(INDEX(Ingredients!$B$2:$B$200,MATCH($B11,Ingredients!$A$2:$A$200,0)),"") | B11: ING-009 | C11: =IFERROR(INDEX(Ingredients!$D$2:$D$200,MATCH($B11,Ingredients!$A$2:$A$200,0)),"") | D11: =SUMIFS(Recipes!$E$2:$E$1000,Recipes!$A$2:$A$1000,D$2,Recipes!$C$2:$C$1000,$B11) | E11: =SUMIFS(Recipes!$E$2:$E$1000,Recipes!$A$2:$A$1000,E$2,Recipes!$C$2:$C$1000,$B11) | F11: =SUMIFS(Recipes!$E$2:$E$1000,Recipes!$A$2:$A$1000,F$2,Recipes!$C$2:$C$1000,$B11) | G11: =SUMIFS(Recipes!$E$2:$E$1000,Recipes!$A$2:$A$1000,G$2,Recipes!$C$2:$C$1000,$B11) | H11: =SUMIFS(Recipes!$E$2:$E$1000,Recipes!$A$2:$A$1000,H$2,Recipes!$C$2:$C$1000,$B11) | I11: =SUMIFS(Recipes!$E$2:$E$1000,Recipes!$A$2:$A$1000,I$2,Recipes!$C$2:$C$1000,$B11) | J11: =SUMIFS(Recipes!$E$2:$E$1000,Recipes!$A$2:$A$1000,J$2,Recipes!$C$2:$C$1000,$B11) | K11: =SUMIFS(Recipes!$E$2:$E$1000,Recipes!$A$2:$A$1000,K$2,Recipes!$C$2:$C$1000,$B11) | ... O11: =SUMIFS(Recipes!$E$2:$E$1000,Recipes!$A$2:$A$1000,O$2,Recipes!$C$2:$C$1000,$B11)
A12: =IFERROR(INDEX(Ingredients!$B$2:$B$200,MATCH($B12,Ingredients!$A$2:$A$200,0)),"") | B12: ING-010 | C12: =IFERROR(INDEX(Ingredients!$D$2:$D$200,MATCH($B12,Ingredients!$A$2:$A$200,0)),"") | D12: =SUMIFS(Recipes!$E$2:$E$1000,Recipes!$A$2:$A$1000,D$2,Recipes!$C$2:$C$1000,$B12) | E12: =SUMIFS(Recipes!$E$2:$E$1000,Recipes!$A$2:$A$1000,E$2,Recipes!$C$2:$C$1000,$B12) | F12: =SUMIFS(Recipes!$E$2:$E$1000,Recipes!$A$2:$A$1000,F$2,Recipes!$C$2:$C$1000,$B12) | G12: =SUMIFS(Recipes!$E$2:$E$1000,Recipes!$A$2:$A$1000,G$2,Recipes!$C$2:$C$1000,$B12) | H12: =SUMIFS(Recipes!$E$2:$E$1000,Recipes!$A$2:$A$1000,H$2,Recipes!$C$2:$C$1000,$B12) | I12: =SUMIFS(Recipes!$E$2:$E$1000,Recipes!$A$2:$A$1000,I$2,Recipes!$C$2:$C$1000,$B12) | J12: =SUMIFS(Recipes!$E$2:$E$1000,Recipes!$A$2:$A$1000,J$2,Recipes!$C$2:$C$1000,$B12) | K12: =SUMIFS(Recipes!$E$2:$E$1000,Recipes!$A$2:$A$1000,K$2,Recipes!$C$2:$C$1000,$B12) | ... O12: =SUMIFS(Recipes!$E$2:$E$1000,Recipes!$A$2:$A$1000,O$2,Recipes!$C$2:$C$1000,$B12)
A13: =IFERROR(INDEX(Ingredients!$B$2:$B$200,MATCH($B13,Ingredients!$A$2:$A$200,0)),"") | B13: ING-011 | C13: =IFERROR(INDEX(Ingredients!$D$2:$D$200,MATCH($B13,Ingredients!$A$2:$A$200,0)),"") | D13: =SUMIFS(Recipes!$E$2:$E$1000,Recipes!$A$2:$A$1000,D$2,Recipes!$C$2:$C$1000,$B13) | E13: =SUMIFS(Recipes!$E$2:$E$1000,Recipes!$A$2:$A$1000,E$2,Recipes!$C$2:$C$1000,$B13) | F13: =SUMIFS(Recipes!$E$2:$E$1000,Recipes!$A$2:$A$1000,F$2,Recipes!$C$2:$C$1000,$B13) | G13: =SUMIFS(Recipes!$E$2:$E$1000,Recipes!$A$2:$A$1000,G$2,Recipes!$C$2:$C$1000,$B13) | H13: =SUMIFS(Recipes!$E$2:$E$1000,Recipes!$A$2:$A$1000,H$2,Recipes!$C$2:$C$1000,$B13) | I13: =SUMIFS(Recipes!$E$2:$E$1000,Recipes!$A$2:$A$1000,I$2,Recipes!$C$2:$C$1000,$B13) | J13: =SUMIFS(Recipes!$E$2:$E$1000,Recipes!$A$2:$A$1000,J$2,Recipes!$C$2:$C$1000,$B13) | K13: =SUMIFS(Recipes!$E$2:$E$1000,Recipes!$A$2:$A$1000,K$2,Recipes!$C$2:$C$1000,$B13) | ... O13: =SUMIFS(Recipes!$E$2:$E$1000,Recipes!$A$2:$A$1000,O$2,Recipes!$C$2:$C$1000,$B13)
A14: =IFERROR(INDEX(Ingredients!$B$2:$B$200,MATCH($B14,Ingredients!$A$2:$A$200,0)),"") | B14: ING-012 | C14: =IFERROR(INDEX(Ingredients!$D$2:$D$200,MATCH($B14,Ingredients!$A$2:$A$200,0)),"") | D14: =SUMIFS(Recipes!$E$2:$E$1000,Recipes!$A$2:$A$1000,D$2,Recipes!$C$2:$C$1000,$B14) | E14: =SUMIFS(Recipes!$E$2:$E$1000,Recipes!$A$2:$A$1000,E$2,Recipes!$C$2:$C$1000,$B14) | F14: =SUMIFS(Recipes!$E$2:$E$1000,Recipes!$A$2:$A$1000,F$2,Recipes!$C$2:$C$1000,$B14) | G14: =SUMIFS(Recipes!$E$2:$E$1000,Recipes!$A$2:$A$1000,G$2,Recipes!$C$2:$C$1000,$B14) | H14: =SUMIFS(Recipes!$E$2:$E$1000,Recipes!$A$2:$A$1000,H$2,Recipes!$C$2:$C$1000,$B14) | I14: =SUMIFS(Recipes!$E$2:$E$1000,Recipes!$A$2:$A$1000,I$2,Recipes!$C$2:$C$1000,$B14) | J14: =SUMIFS(Recipes!$E$2:$E$1000,Recipes!$A$2:$A$1000,J$2,Recipes!$C$2:$C$1000,$B14) | K14: =SUMIFS(Recipes!$E$2:$E$1000,Recipes!$A$2:$A$1000,K$2,Recipes!$C$2:$C$1000,$B14) | ... O14: =SUMIFS(Recipes!$E$2:$E$1000,Recipes!$A$2:$A$1000,O$2,Recipes!$C$2:$C$1000,$B14)
... A33: =IFERROR(INDEX(Ingredients!$B$2:$B$200,MATCH($B33,Ingredients!$A$2:$A$200,0)),"") | B33: ING-031 | C33: =IFERROR(INDEX(Ingredients!$D$2:$D$200,MATCH($B33,Ingredients!$A$2:$A$200,0)),"") | D33: =SUMIFS(Recipes!$E$2:$E$1000,Recipes!$A$2:$A$1000,D$2,Recipes!$C$2:$C$1000,$B33) | E33: =SUMIFS(Recipes!$E$2:$E$1000,Recipes!$A$2:$A$1000,E$2,Recipes!$C$2:$C$1000,$B33) | F33: =SUMIFS(Recipes!$E$2:$E$1000,Recipes!$A$2:$A$1000,F$2,Recipes!$C$2:$C$1000,$B33) | G33: =SUMIFS(Recipes!$E$2:$E$1000,Recipes!$A$2:$A$1000,G$2,Recipes!$C$2:$C$1000,$B33) | H33: =SUMIFS(Recipes!$E$2:$E$1000,Recipes!$A$2:$A$1000,H$2,Recipes!$C$2:$C$1000,$B33) | I33: =SUMIFS(Recipes!$E$2:$E$1000,Recipes!$A$2:$A$1000,I$2,Recipes!$C$2:$C$1000,$B33) | J33: =SUMIFS(Recipes!$E$2:$E$1000,Recipes!$A$2:$A$1000,J$2,Recipes!$C$2:$C$1000,$B33) | K33: =SUMIFS(Recipes!$E$2:$E$1000,Recipes!$A$2:$A$1000,K$2,Recipes!$C$2:$C$1000,$B33) | ... O33: =SUMIFS(Recipes!$E$2:$E$1000,Recipes!$A$2:$A$1000,O$2,Recipes!$C$2:$C$1000,$B33)

Sheet Procurement
A1: Supplier | B1: Ingredient | C1: Supplier SKU | D1: Package | E1: On Hand | F1: Reorder Point | G1: Status | H1: Order (pkgs) | I1: Lead Time (days) | J1: Order Cost ($) | K1: Expected Arrival
A2: =Ingredients!E24 | B2: =Ingredients!B24 | C2: =Ingredients!F24 | D2: =Ingredients!G24 | E2: =Ingredients!O24 | F2: =Ingredients!P24 | G2: =Ingredients!T24 | H2: =Ingredients!U24 | I2: =Ingredients!L24 | J2: =Ingredients!V24 | K2: =IF(G2="REORDER",TODAY()+I2,"")
A3: =Ingredients!E31 | B3: =Ingredients!B31 | C3: =Ingredients!F31 | D3: =Ingredients!G31 | E3: =Ingredients!O31 | F3: =Ingredients!P31 | G3: =Ingredients!T31 | H3: =Ingredients!U31 | I3: =Ingredients!L31 | J3: =Ingredients!V31 | K3: =IF(G3="REORDER",TODAY()+I3,"")
A4: =Ingredients!E32 | B4: =Ingredients!B32 | C4: =Ingredients!F32 | D4: =Ingredients!G32 | E4: =Ingredients!O32 | F4: =Ingredients!P32 | G4: =Ingredients!T32 | H4: =Ingredients!U32 | I4: =Ingredients!L32 | J4: =Ingredients!V32 | K4: =IF(G4="REORDER",TODAY()+I4,"")
A5: =Ingredients!E12 | B5: =Ingredients!B12 | C5: =Ingredients!F12 | D5: =Ingredients!G12 | E5: =Ingredients!O12 | F5: =Ingredients!P12 | G5: =Ingredients!T12 | H5: =Ingredients!U12 | I5: =Ingredients!L12 | J5: =Ingredients!V12 | K5: =IF(G5="REORDER",TODAY()+I5,"")
A6: =Ingredients!E10 | B6: =Ingredients!B10 | C6: =Ingredients!F10 | D6: =Ingredients!G10 | E6: =Ingredients!O10 | F6: =Ingredients!P10 | G6: =Ingredients!T10 | H6: =Ingredients!U10 | I6: =Ingredients!L10 | J6: =Ingredients!V10 | K6: =IF(G6="REORDER",TODAY()+I6,"")
A7: =Ingredients!E11 | B7: =Ingredients!B11 | C7: =Ingredients!F11 | D7: =Ingredients!G11 | E7: =Ingredients!O11 | F7: =Ingredients!P11 | G7: =Ingredients!T11 | H7: =Ingredients!U11 | I7: =Ingredients!L11 | J7: =Ingredients!V11 | K7: =IF(G7="REORDER",TODAY()+I7,"")
A8: =Ingredients!E9 | B8: =Ingredients!B9 | C8: =Ingredients!F9 | D8: =Ingredients!G9 | E8: =Ingredients!O9 | F8: =Ingredients!P9 | G8: =Ingredients!T9 | H8: =Ingredients!U9 | I8: =Ingredients!L9 | J8: =Ingredients!V9 | K8: =IF(G8="REORDER",TODAY()+I8,"")
A9: =Ingredients!E8 | B9: =Ingredients!B8 | C9: =Ingredients!F8 | D9: =Ingredients!G8 | E9: =Ingredients!O8 | F9: =Ingredients!P8 | G9: =Ingredients!T8 | H9: =Ingredients!U8 | I9: =Ingredients!L8 | J9: =Ingredients!V8 | K9: =IF(G9="REORDER",TODAY()+I9,"")
A10: =Ingredients!E20 | B10: =Ingredients!B20 | C10: =Ingredients!F20 | D10: =Ingredients!G20 | E10: =Ingredients!O20 | F10: =Ingredients!P20 | G10: =Ingredients!T20 | H10: =Ingredients!U20 | I10: =Ingredients!L20 | J10: =Ingredients!V20 | K10: =IF(G10="REORDER",TODAY()+I10,"")
A11: =Ingredients!E19 | B11: =Ingredients!B19 | C11: =Ingredients!F19 | D11: =Ingredients!G19 | E11: =Ingredients!O19 | F11: =Ingredients!P19 | G11: =Ingredients!T19 | H11: =Ingredients!U19 | I11: =Ingredients!L19 | J11: =Ingredients!V19 | K11: =IF(G11="REORDER",TODAY()+I11,"")
A12: =Ingredients!E18 | B12: =Ingredients!B18 | C12: =Ingredients!F18 | D12: =Ingredients!G18 | E12: =Ingredients!O18 | F12: =Ingredients!P18 | G12: =Ingredients!T18 | H12: =Ingredients!U18 | I12: =Ingredients!L18 | J12: =Ingredients!V18 | K12: =IF(G12="REORDER",TODAY()+I12,"")
A13: =Ingredients!E17 | B13: =Ingredients!B17 | C13: =Ingredients!F17 | D13: =Ingredients!G17 | E13: =Ingredients!O17 | F13: =Ingredients!P17 | G13: =Ingredients!T17 | H13: =Ingredients!U17 | I13: =Ingredients!L17 | J13: =Ingredients!V17 | K13: =IF(G13="REORDER",TODAY()+I13,"")
A14: =Ingredients!E21 | B14: =Ingredients!B21 | C14: =Ingredients!F21 | D14: =Ingredients!G21 | E14: =Ingredients!O21 | F14: =Ingredients!P21 | G14: =Ingredients!T21 | H14: =Ingredients!U21 | I14: =Ingredients!L21 | J14: =Ingredients!V21 | K14: =IF(G14="REORDER",TODAY()+I14,"")
A15: =Ingredients!E16 | B15: =Ingredients!B16 | C15: =Ingredients!F16 | D15: =Ingredients!G16 | E15: =Ingredients!O16 | F15: =Ingredients!P16 | G15: =Ingredients!T16 | H15: =Ingredients!U16 | I15: =Ingredients!L16 | J15: =Ingredients!V16 | K15: =IF(G15="REORDER",TODAY()+I15,"")
A16: =Ingredients!E14 | B16: =Ingredients!B14 | C16: =Ingredients!F14 | D16: =Ingredients!G14 | E16: =Ingredients!O14 | F16: =Ingredients!P14 | G16: =Ingredients!T14 | H16: =Ingredients!U14 | I16: =Ingredients!L14 | J16: =Ingredients!V14 | K16: =IF(G16="REORDER",TODAY()+I16,"")
A17: =Ingredients!E23 | B17: =Ingredients!B23 | C17: =Ingredients!F23 | D17: =Ingredients!G23 | E17: =Ingredients!O23 | F17: =Ingredients!P23 | G17: =Ingredients!T23 | H17: =Ingredients!U23 | I17: =Ingredients!L23 | J17: =Ingredients!V23 | K17: =IF(G17="REORDER",TODAY()+I17,"")
A18: =Ingredients!E13 | B18: =Ingredients!B13 | C18: =Ingredients!F13 | D18: =Ingredients!G13 | E18: =Ingredients!O13 | F18: =Ingredients!P13 | G18: =Ingredients!T13 | H18: =Ingredients!U13 | I18: =Ingredients!L13 | J18: =Ingredients!V13 | K18: =IF(G18="REORDER",TODAY()+I18,"")
A19: =Ingredients!E15 | B19: =Ingredients!B15 | C19: =Ingredients!F15 | D19: =Ingredients!G15 | E19: =Ingredients!O15 | F19: =Ingredients!P15 | G19: =Ingredients!T15 | H19: =Ingredients!U15 | I19: =Ingredients!L15 | J19: =Ingredients!V15 | K19: =IF(G19="REORDER",TODAY()+I19,"")
A20: =Ingredients!E22 | B20: =Ingredients!B22 | C20: =Ingredients!F22 | D20: =Ingredients!G22 | E20: =Ingredients!O22 | F20: =Ingredients!P22 | G20: =Ingredients!T22 | H20: =Ingredients!U22 | I20: =Ingredients!L22 | J20: =Ingredients!V22 | K20: =IF(G20="REORDER",TODAY()+I20,"")
A21: =Ingredients!E30 | B21: =Ingredients!B30 | C21: =Ingredients!F30 | D21: =Ingredients!G30 | E21: =Ingredients!O30 | F21: =Ingredients!P30 | G21: =Ingredients!T30 | H21: =Ingredients!U30 | I21: =Ingredients!L30 | J21: =Ingredients!V30 | K21: =IF(G21="REORDER",TODAY()+I21,"")
A22: =Ingredients!E29 | B22: =Ingredients!B29 | C22: =Ingredients!F29 | D22: =Ingredients!G29 | E22: =Ingredients!O29 | F22: =Ingredients!P29 | G22: =Ingredients!T29 | H22: =Ingredients!U29 | I22: =Ingredients!L29 | J22: =Ingredients!V29 | K22: =IF(G22="REORDER",TODAY()+I22,"")
A23: =Ingredients!E5 | B23: =Ingredients!B5 | C23: =Ingredients!F5 | D23: =Ingredients!G5 | E23: =Ingredients!O5 | F23: =Ingredients!P5 | G23: =Ingredients!T5 | H23: =Ingredients!U5 | I23: =Ingredients!L5 | J23: =Ingredients!V5 | K23: =IF(G23="REORDER",TODAY()+I23,"")
A24: =Ingredients!E27 | B24: =Ingredients!B27 | C24: =Ingredients!F27 | D24: =Ingredients!G27 | E24: =Ingredients!O27 | F24: =Ingredients!P27 | G24: =Ingredients!T27 | H24: =Ingredients!U27 | I24: =Ingredients!L27 | J24: =Ingredients!V27 | K24: =IF(G24="REORDER",TODAY()+I24,"")
A25: =Ingredients!E26 | B25: =Ingredients!B26 | C25: =Ingredients!F26 | D25: =Ingredients!G26 | E25: =Ingredients!O26 | F25: =Ingredients!P26 | G25: =Ingredients!T26 | H25: =Ingredients!U26 | I25: =Ingredients!L26 | J25: =Ingredients!V26 | K25: =IF(G25="REORDER",TODAY()+I25,"")
A26: =Ingredients!E25 | B26: =Ingredients!B25 | C26: =Ingredients!F25 | D26: =Ingredients!G25 | E26: =Ingredients!O25 | F26: =Ingredients!P25 | G26: =Ingredients!T25 | H26: =Ingredients!U25 | I26: =Ingredients!L25 | J26: =Ingredients!V25 | K26: =IF(G26="REORDER",TODAY()+I26,"")
A27: =Ingredients!E6 | B27: =Ingredients!B6 | C27: =Ingredients!F6 | D27: =Ingredients!G6 | E27: =Ingredients!O6 | F27: =Ingredients!P6 | G27: =Ingredients!T6 | H27: =Ingredients!U6 | I27: =Ingredients!L6 | J27: =Ingredients!V6 | K27: =IF(G27="REORDER",TODAY()+I27,"")
A28: =Ingredients!E7 | B28: =Ingredients!B7 | C28: =Ingredients!F7 | D28: =Ingredients!G7 | E28: =Ingredients!O7 | F28: =Ingredients!P7 | G28: =Ingredients!T7 | H28: =Ingredients!U7 | I28: =Ingredients!L7 | J28: =Ingredients!V7 | K28: =IF(G28="REORDER",TODAY()+I28,"")
A29: =Ingredients!E28 | B29: =Ingredients!B28 | C29: =Ingredients!F28 | D29: =Ingredients!G28 | E29: =Ingredients!O28 | F29: =Ingredients!P28 | G29: =Ingredients!T28 | H29: =Ingredients!U28 | I29: =Ingredients!L28 | J29: =Ingredients!V28 | K29: =IF(G29="REORDER",TODAY()+I29,"")
A30: =Ingredients!E2 | B30: =Ingredients!B2 | C30: =Ingredients!F2 | D30: =Ingredients!G2 | E30: =Ingredients!O2 | F30: =Ingredients!P2 | G30: =Ingredients!T2 | H30: =Ingredients!U2 | I30: =Ingredients!L2 | J30: =Ingredients!V2 | K30: =IF(G30="REORDER",TODAY()+I30,"")
A31: =Ingredients!E3 | B31: =Ingredients!B3 | C31: =Ingredients!F3 | D31: =Ingredients!G3 | E31: =Ingredients!O3 | F31: =Ingredients!P3 | G31: =Ingredients!T3 | H31: =Ingredients!U3 | I31: =Ingredients!L3 | J31: =Ingredients!V3 | K31: =IF(G31="REORDER",TODAY()+I31,"")
A32: =Ingredients!E4 | B32: =Ingredients!B4 | C32: =Ingredients!F4 | D32: =Ingredients!G4 | E32: =Ingredients!O4 | F32: =Ingredients!P4 | G32: =Ingredients!T4 | H32: =Ingredients!U4 | I32: =Ingredients!L4 | J32: =Ingredients!V4 | K32: =IF(G32="REORDER",TODAY()+I32,"")
A34: Total to order | J34: =SUM(J2:J32)

Sheet Purchase Orders
A1: PO # | B1: Supplier | C1: Created | D1: Expected | E1: Status | F1: Ingredient ID | G1: Ingredient | H1: Ordered (pkgs) | I1: Received OK (pkgs) | J1: Damaged (pkgs) | K1: Outstanding (pkgs) | L1: Package Cost ($) | M1: Shipping ($) | N1: Line Total ($)
A2: PO-001 | B2: GreenLeaf Produce | C2: 2026-10-16 | D2: 2026-10-18 | E2: received | F2: ING-014 | G2: Spinach | H2: 6 | I2: 6 | J2: 0 | K2: =IF(OR(E2="open",E2="partial"),MAX(H2-I2,0),0) | L2: 14 | M2: 2.5 | N2: =H2*(L2+M2)
A3: PO-001 | B3: GreenLeaf Produce | C3: 2026-10-16 | D3: 2026-10-18 | E3: received | F3: ING-007 | G3: Banana | H3: 2 | I3: 2 | J3: 0 | K3: =IF(OR(E3="open",E3="partial"),MAX(H3-I3,0),0) | L3: 28 | M3: 4 | N3: =H3*(L3+M3)
A4: PO-002 | B4: Frosty Farms | C4: 2026-10-17 | D4: 2026-10-22 | E4: partial | F4: ING-008 | G4: Strawberries (frozen) | H4: 4 | I4: 4 | J4: 0 | K4: =IF(OR(E4="open",E4="partial"),MAX(H4-I4,0),0) | L4: 42 | M4: 8 | N4: =H4*(L4+M4)
A5: PO-002 | B5: Frosty Farms | C5: 2026-10-17 | D5: 2026-10-22 | E5: partial | F5: ING-010 | G5: Peach (frozen) | H5: 3 | I5: 2 | J5: 1 | K5: =IF(OR(E5="open",E5="partial"),MAX(H5-I5,0),0) | L5: 44 | M5: 8 | N5: =H5*(L5+M5)
A6: PO-003 | B6: Sysco | C6: 2026-10-21 | D6: 2026-10-25 | E6: open | F6: ING-006 | G6: Greek Yogurt | H6: 7 | I6: 0 | J6: 0 | K6: =IF(OR(E6="open",E6="partial"),MAX(H6-I6,0),0) | L6: 27 | M6: 3 | N6: =H6*(L6+M6)
A7: PO-003 | B7: Sysco | C7: 2026-10-21 | D7: 2026-10-25 | E7: open | F7: ING-005 | G7: Almond Milk | H7: 2 | I7: 0 | J7: 0 | K7: =IF(OR(E7="open",E7="partial"),MAX(H7-I7,0),0) | L7: 21 | M7: 3 | N7: =H7*(L7+M7)
A8: PO-004 | B8: Island Imports | C8: 2026-10-13 | D8: 2026-10-27 | E8: open | F8: ING-028 | G8: Acai Packs (frozen) | H8: 9 | I8: 0 | J8: 0 | K8: =IF(OR(E8="open",E8="partial"),MAX(H8-I8,0),0) | L8: 62 | M8: 9 | N8: =H8*(L8+M8)

Sheet Receiving Log
A1: Received At | B1: Receipt # | C1: PO # | D1: Supplier | E1: Received By | F1: Tracking / Invoice # | G1: Late? | H1: Box Damaged? | I1: Wrong Items? | J1: Ingredient | K1: Expected (pkgs) | L1: Received OK (pkgs) | M1: Damaged (pkgs) | N1: Short (pkgs) | O1: Item Note | P1: Delivery Notes
A2: 2026-10-23 09:40 | B2: RC-002 | C2: PO-002 | D2: Frosty Farms | E2: Maya Torres | F2: FF-209331 | G2: Yes | H2: Yes | J2: Strawberries (frozen) | K2: 4 | L2: 4 | M2: 0 | N2: =MAX(K2-L2,0) | P2: Outer box crushed on one side. Driver signed the damage note.
A3: 2026-10-23 09:40 | B3: RC-002 | C3: PO-002 | D3: Frosty Farms | E3: Maya Torres | F3: FF-209331 | G3: Yes | H3: Yes | J3: Peach (frozen) | K3: 3 | L3: 2 | M3: 1 | N3: =MAX(K3-L3,0) | O3: Bags split, thawed. Photo taken; supplier to credit or resend. | P3: Outer box crushed on one side. Driver signed the damage note.
A4: 2026-10-18 08:15 | B4: RC-001 | C4: PO-001 | D4: GreenLeaf Produce | E4: Jordan Lee | F4: INV-44817 | J4: Spinach | K4: 6 | L4: 6 | M4: 0 | N4: =MAX(K4-L4,0)
A5: 2026-10-18 08:15 | B5: RC-001 | C5: PO-001 | D5: GreenLeaf Produce | E5: Jordan Lee | F5: INV-44817 | J5: Banana | K5: 2 | L5: 2 | M5: 0 | N5: =MAX(K5-L5,0)

Sheet Sales Log
A1: Date / Time | B1: Item ID | C1: Qty | D1: Item Name | E1: Revenue ($)
A2: 2026-10-11 08:00:00 | B2: MI-001 | C2: 15 | D2: =IFERROR(INDEX('Menu Items'!$B$2:$B$200,MATCH(B2,'Menu Items'!$A$2:$A$200,0)),"") | E2: =IFERROR(C2*INDEX('Menu Items'!$E$2:$E$200,MATCH(B2,'Menu Items'!$A$2:$A$200,0)),0)
A3: 2026-10-11 08:00:00 | B3: MI-007 | C3: 13 | D3: =IFERROR(INDEX('Menu Items'!$B$2:$B$200,MATCH(B3,'Menu Items'!$A$2:$A$200,0)),"") | E3: =IFERROR(C3*INDEX('Menu Items'!$E$2:$E$200,MATCH(B3,'Menu Items'!$A$2:$A$200,0)),0)
A4: 2026-10-11 09:00:00 | B4: MI-005 | C4: 29 | D4: =IFERROR(INDEX('Menu Items'!$B$2:$B$200,MATCH(B4,'Menu Items'!$A$2:$A$200,0)),"") | E4: =IFERROR(C4*INDEX('Menu Items'!$E$2:$E$200,MATCH(B4,'Menu Items'!$A$2:$A$200,0)),0)
A5: 2026-10-11 10:00:00 | B5: MI-003 | C5: 19 | D5: =IFERROR(INDEX('Menu Items'!$B$2:$B$200,MATCH(B5,'Menu Items'!$A$2:$A$200,0)),"") | E5: =IFERROR(C5*INDEX('Menu Items'!$E$2:$E$200,MATCH(B5,'Menu Items'!$A$2:$A$200,0)),0)
A6: 2026-10-11 11:00:00 | B6: MI-002 | C6: 20 | D6: =IFERROR(INDEX('Menu Items'!$B$2:$B$200,MATCH(B6,'Menu Items'!$A$2:$A$200,0)),"") | E6: =IFERROR(C6*INDEX('Menu Items'!$E$2:$E$200,MATCH(B6,'Menu Items'!$A$2:$A$200,0)),0)
A7: 2026-10-11 11:00:00 | B7: MI-008 | C7: 14 | D7: =IFERROR(INDEX('Menu Items'!$B$2:$B$200,MATCH(B7,'Menu Items'!$A$2:$A$200,0)),"") | E7: =IFERROR(C7*INDEX('Menu Items'!$E$2:$E$200,MATCH(B7,'Menu Items'!$A$2:$A$200,0)),0)
A8: 2026-10-11 14:00:00 | B8: MI-006 | C8: 30 | D8: =IFERROR(INDEX('Menu Items'!$B$2:$B$200,MATCH(B8,'Menu Items'!$A$2:$A$200,0)),"") | E8: =IFERROR(C8*INDEX('Menu Items'!$E$2:$E$200,MATCH(B8,'Menu Items'!$A$2:$A$200,0)),0)
A9: 2026-10-11 14:00:00 | B9: MI-012 | C9: 29 | D9: =IFERROR(INDEX('Menu Items'!$B$2:$B$200,MATCH(B9,'Menu Items'!$A$2:$A$200,0)),"") | E9: =IFERROR(C9*INDEX('Menu Items'!$E$2:$E$200,MATCH(B9,'Menu Items'!$A$2:$A$200,0)),0)
A10: 2026-10-11 16:00:00 | B10: MI-009 | C10: 19 | D10: =IFERROR(INDEX('Menu Items'!$B$2:$B$200,MATCH(B10,'Menu Items'!$A$2:$A$200,0)),"") | E10: =IFERROR(C10*INDEX('Menu Items'!$E$2:$E$200,MATCH(B10,'Menu Items'!$A$2:$A$200,0)),0)
A11: 2026-10-11 16:00:00 | B11: MI-010 | C11: 12 | D11: =IFERROR(INDEX('Menu Items'!$B$2:$B$200,MATCH(B11,'Menu Items'!$A$2:$A$200,0)),"") | E11: =IFERROR(C11*INDEX('Menu Items'!$E$2:$E$200,MATCH(B11,'Menu Items'!$A$2:$A$200,0)),0)
A12: 2026-10-11 18:00:00 | B12: MI-004 | C12: 15 | D12: =IFERROR(INDEX('Menu Items'!$B$2:$B$200,MATCH(B12,'Menu Items'!$A$2:$A$200,0)),"") | E12: =IFERROR(C12*INDEX('Menu Items'!$E$2:$E$200,MATCH(B12,'Menu Items'!$A$2:$A$200,0)),0)
A13: 2026-10-11 18:00:00 | B13: MI-011 | C13: 18 | D13: =IFERROR(INDEX('Menu Items'!$B$2:$B$200,MATCH(B13,'Menu Items'!$A$2:$A$200,0)),"") | E13: =IFERROR(C13*INDEX('Menu Items'!$E$2:$E$200,MATCH(B13,'Menu Items'!$A$2:$A$200,0)),0)
... A169: 2026-10-24 18:00:00 | B169: MI-009 | C169: 16 | D169: =IFERROR(INDEX('Menu Items'!$B$2:$B$200,MATCH(B169,'Menu Items'!$A$2:$A$200,0)),"") | E169: =IFERROR(C169*INDEX('Menu Items'!$E$2:$E$200,MATCH(B169,'Menu Items'!$A$2:$A$200,0)),0)

Sheet Staff
A1: Employee ID | B1: Name | C1: Role | D1: Hourly Rate ($) | E1: Max Hours / Week | F1: Phone | G1: Email | H1: Active
A2: EMP-001 | B2: Maya Torres | C2: Manager | D2: 24 | E2: 40 | H2: Yes
A3: EMP-002 | B3: Jordan Lee | C3: Shift Lead | D3: 19.5 | E3: 40 | H3: Yes
A4: EMP-003 | B4: Sam Patel | C4: Juicer | D4: 16.5 | E4: 40 | H4: Yes
A5: EMP-004 | B5: Alex Kim | C5: Juicer | D5: 16 | E5: 30 | H5: Yes
A6: EMP-005 | B6: Riley Chen | C6: Juicer | D6: 16 | E6: 30 | H6: Yes
A7: EMP-006 | B7: Casey Brooks | C7: Cashier | D7: 15.5 | E7: 28 | H7: Yes

Sheet Schedule
A1: Shift ID | B1: Date | C1: Day | D1: Employee ID | E1: Employee | F1: Role | G1: Start | H1: End | I1: Hours | J1: Hourly Rate ($) | K1: Labor Cost ($) | L1: Week Of | M1: Notes
A2: SH-001 | B2: 46307 | C2: =TEXT(B2,"ddd") | D2: EMP-001 | E2: =IF(D2="OPEN","OPEN SHIFT",IFERROR(INDEX(Staff!$B$2:$B$100,MATCH(D2,Staff!$A$2:$A$100,0)),"")) | F2: Manager | G2: 0.27083333 | H2: 0.60416667 | I2: =MOD(H2-G2,1)*24 | J2: =IFERROR(INDEX(Staff!$D$2:$D$100,MATCH(D2,Staff!$A$2:$A$100,0)),0) | K2: =I2*J2 | L2: =B2-WEEKDAY(B2,3)
A3: SH-011 | B3: 46307 | C3: =TEXT(B3,"ddd") | D3: EMP-003 | E3: =IF(D3="OPEN","OPEN SHIFT",IFERROR(INDEX(Staff!$B$2:$B$100,MATCH(D3,Staff!$A$2:$A$100,0)),"")) | F3: Juicer | G3: 0.27083333 | H3: 0.60416667 | I3: =MOD(H3-G3,1)*24 | J3: =IFERROR(INDEX(Staff!$D$2:$D$100,MATCH(D3,Staff!$A$2:$A$100,0)),0) | K3: =I3*J3 | L3: =B3-WEEKDAY(B3,3)
A4: SH-024 | B4: 46307 | C4: =TEXT(B4,"ddd") | D4: EMP-006 | E4: =IF(D4="OPEN","OPEN SHIFT",IFERROR(INDEX(Staff!$B$2:$B$100,MATCH(D4,Staff!$A$2:$A$100,0)),"")) | F4: Cashier | G4: 0.41666667 | H4: 0.66666667 | I4: =MOD(H4-G4,1)*24 | J4: =IFERROR(INDEX(Staff!$D$2:$D$100,MATCH(D4,Staff!$A$2:$A$100,0)),0) | K4: =I4*J4 | L4: =B4-WEEKDAY(B4,3)
A5: SH-006 | B5: 46307 | C5: =TEXT(B5,"ddd") | D5: EMP-002 | E5: =IF(D5="OPEN","OPEN SHIFT",IFERROR(INDEX(Staff!$B$2:$B$100,MATCH(D5,Staff!$A$2:$A$100,0)),"")) | F5: Shift Lead | G5: 0.54166667 | H5: 0.83333333 | I5: =MOD(H5-G5,1)*24 | J5: =IFERROR(INDEX(Staff!$D$2:$D$100,MATCH(D5,Staff!$A$2:$A$100,0)),0) | K5: =I5*J5 | L5: =B5-WEEKDAY(B5,3)
A6: SH-002 | B6: 46308 | C6: =TEXT(B6,"ddd") | D6: EMP-001 | E6: =IF(D6="OPEN","OPEN SHIFT",IFERROR(INDEX(Staff!$B$2:$B$100,MATCH(D6,Staff!$A$2:$A$100,0)),"")) | F6: Manager | G6: 0.27083333 | H6: 0.60416667 | I6: =MOD(H6-G6,1)*24 | J6: =IFERROR(INDEX(Staff!$D$2:$D$100,MATCH(D6,Staff!$A$2:$A$100,0)),0) | K6: =I6*J6 | L6: =B6-WEEKDAY(B6,3)
A7: SH-012 | B7: 46308 | C7: =TEXT(B7,"ddd") | D7: EMP-003 | E7: =IF(D7="OPEN","OPEN SHIFT",IFERROR(INDEX(Staff!$B$2:$B$100,MATCH(D7,Staff!$A$2:$A$100,0)),"")) | F7: Juicer | G7: 0.27083333 | H7: 0.60416667 | I7: =MOD(H7-G7,1)*24 | J7: =IFERROR(INDEX(Staff!$D$2:$D$100,MATCH(D7,Staff!$A$2:$A$100,0)),0) | K7: =I7*J7 | L7: =B7-WEEKDAY(B7,3)
A8: SH-025 | B8: 46308 | C8: =TEXT(B8,"ddd") | D8: EMP-006 | E8: =IF(D8="OPEN","OPEN SHIFT",IFERROR(INDEX(Staff!$B$2:$B$100,MATCH(D8,Staff!$A$2:$A$100,0)),"")) | F8: Cashier | G8: 0.41666667 | H8: 0.66666667 | I8: =MOD(H8-G8,1)*24 | J8: =IFERROR(INDEX(Staff!$D$2:$D$100,MATCH(D8,Staff!$A$2:$A$100,0)),0) | K8: =I8*J8 | L8: =B8-WEEKDAY(B8,3)
A9: SH-007 | B9: 46308 | C9: =TEXT(B9,"ddd") | D9: EMP-002 | E9: =IF(D9="OPEN","OPEN SHIFT",IFERROR(INDEX(Staff!$B$2:$B$100,MATCH(D9,Staff!$A$2:$A$100,0)),"")) | F9: Shift Lead | G9: 0.54166667 | H9: 0.83333333 | I9: =MOD(H9-G9,1)*24 | J9: =IFERROR(INDEX(Staff!$D$2:$D$100,MATCH(D9,Staff!$A$2:$A$100,0)),0) | K9: =I9*J9 | L9: =B9-WEEKDAY(B9,3)
A10: SH-003 | B10: 46309 | C10: =TEXT(B10,"ddd") | D10: EMP-001 | E10: =IF(D10="OPEN","OPEN SHIFT",IFERROR(INDEX(Staff!$B$2:$B$100,MATCH(D10,Staff!$A$2:$A$100,0)),"")) | F10: Manager | G10: 0.27083333 | H10: 0.60416667 | I10: =MOD(H10-G10,1)*24 | J10: =IFERROR(INDEX(Staff!$D$2:$D$100,MATCH(D10,Staff!$A$2:$A$100,0)),0) | K10: =I10*J10 | L10: =B10-WEEKDAY(B10,3)
A11: SH-008 | B11: 46309 | C11: =TEXT(B11,"ddd") | D11: EMP-002 | E11: =IF(D11="OPEN","OPEN SHIFT",IFERROR(INDEX(Staff!$B$2:$B$100,MATCH(D11,Staff!$A$2:$A$100,0)),"")) | F11: Shift Lead | G11: 0.54166667 | H11: 0.83333333 | I11: =MOD(H11-G11,1)*24 | J11: =IFERROR(INDEX(Staff!$D$2:$D$100,MATCH(D11,Staff!$A$2:$A$100,0)),0) | K11: =I11*J11 | L11: =B11-WEEKDAY(B11,3)
A12: SH-016 | B12: 46309 | C12: =TEXT(B12,"ddd") | D12: EMP-004 | E12: =IF(D12="OPEN","OPEN SHIFT",IFERROR(INDEX(Staff!$B$2:$B$100,MATCH(D12,Staff!$A$2:$A$100,0)),"")) | F12: Juicer | G12: 0.54166667 | H12: 0.83333333 | I12: =MOD(H12-G12,1)*24 | J12: =IFERROR(INDEX(Staff!$D$2:$D$100,MATCH(D12,Staff!$A$2:$A$100,0)),0) | K12: =I12*J12 | L12: =B12-WEEKDAY(B12,3)
A13: SH-004 | B13: 46310 | C13: =TEXT(B13,"ddd") | D13: EMP-001 | E13: =IF(D13="OPEN","OPEN SHIFT",IFERROR(INDEX(Staff!$B$2:$B$100,MATCH(D13,Staff!$A$2:$A$100,0)),"")) | F13: Manager | G13: 0.27083333 | H13: 0.60416667 | I13: =MOD(H13-G13,1)*24 | J13: =IFERROR(INDEX(Staff!$D$2:$D$100,MATCH(D13,Staff!$A$2:$A$100,0)),0) | K13: =I13*J13 | L13: =B13-WEEKDAY(B13,3)
... A51: SH-044 | B51: 46319 | C51: =TEXT(B51,"ddd") | D51: EMP-004 | E51: =IF(D51="OPEN","OPEN SHIFT",IFERROR(INDEX(Staff!$B$2:$B$100,MATCH(D51,Staff!$A$2:$A$100,0)),"")) | F51: Juicer | G51: 0.54166667 | H51: 0.83333333 | I51: =MOD(H51-G51,1)*24 | J51: =IFERROR(INDEX(Staff!$D$2:$D$100,MATCH(D51,Staff!$A$2:$A$100,0)),0) | K51: =I51*J51 | L51: =B51-WEEKDAY(B51,3)
A52: SH-055 | B52: 46319 | C52: =TEXT(B52,"ddd") | D52: OPEN | E52: =IF(D52="OPEN","OPEN SHIFT",IFERROR(INDEX(Staff!$B$2:$B$100,MATCH(D52,Staff!$A$2:$A$100,0)),"")) | F52: Juicer | G52: 0.54166667 | H52: 0.83333333 | I52: =MOD(H52-G52,1)*24 | J52: =IFERROR(INDEX(Staff!$D$2:$D$100,MATCH(D52,Staff!$A$2:$A$100,0)),0) | K52: =I52*J52 | L52: =B52-WEEKDAY(B52,3) | M52: Saturday close
A53: SH-054 | B53: 46320 | C53: =TEXT(B53,"ddd") | D53: EMP-006 | E53: =IF(D53="OPEN","OPEN SHIFT",IFERROR(INDEX(Staff!$B$2:$B$100,MATCH(D53,Staff!$A$2:$A$100,0)),"")) | F53: Cashier | G53: 0.27083333 | H53: 0.60416667 | I53: =MOD(H53-G53,1)*24 | J53: =IFERROR(INDEX(Staff!$D$2:$D$100,MATCH(D53,Staff!$A$2:$A$100,0)),0) | K53: =I53*J53 | L53: =B53-WEEKDAY(B53,3)
A54: SH-049 | B54: 46320 | C54: =TEXT(B54,"ddd") | D54: EMP-005 | E54: =IF(D54="OPEN","OPEN SHIFT",IFERROR(INDEX(Staff!$B$2:$B$100,MATCH(D54,Staff!$A$2:$A$100,0)),"")) | F54: Juicer | G54: 0.41666667 | H54: 0.66666667 | I54: =MOD(H54-G54,1)*24 | J54: =IFERROR(INDEX(Staff!$D$2:$D$100,MATCH(D54,Staff!$A$2:$A$100,0)),0) | K54: =I54*J54 | L54: =B54-WEEKDAY(B54,3)
A55: SH-042 | B55: 46320 | C55: =TEXT(B55,"ddd") | D55: EMP-003 | E55: =IF(D55="OPEN","OPEN SHIFT",IFERROR(INDEX(Staff!$B$2:$B$100,MATCH(D55,Staff!$A$2:$A$100,0)),"")) | F55: Juicer | G55: 0.54166667 | H55: 0.83333333 | I55: =MOD(H55-G55,1)*24 | J55: =IFERROR(INDEX(Staff!$D$2:$D$100,MATCH(D55,Staff!$A$2:$A$100,0)),0) | K55: =I55*J55 | L55: =B55-WEEKDAY(B55,3)
A56: SH-045 | B56: 46320 | C56: =TEXT(B56,"ddd") | D56: EMP-004 | E56: =IF(D56="OPEN","OPEN SHIFT",IFERROR(INDEX(Staff!$B$2:$B$100,MATCH(D56,Staff!$A$2:$A$100,0)),"")) | F56: Juicer | G56: 0.54166667 | H56: 0.83333333 | I56: =MOD(H56-G56,1)*24 | J56: =IFERROR(INDEX(Staff!$D$2:$D$100,MATCH(D56,Staff!$A$2:$A$100,0)),0) | K56: =I56*J56 | L56: =B56-WEEKDAY(B56,3)

Sheet Weekly Hours
A1: Week of | B1: 46314 | C1: Change this Monday date to view another week.
A3: Employee ID | B3: Name | C3: Role | D3: =$B$1+0 | E3: =$B$1+1 | F3: =$B$1+2 | G3: =$B$1+3 | H3: =$B$1+4 | I3: =$B$1+5 | J3: =$B$1+6 | K3: Total Hours | L3: Max Hours | M3: Over Max? | N3: Labor Cost ($)
A4: EMP-001 | B4: Maya Torres | C4: Manager | D4: =SUMIFS(Schedule!$I$2:$I$2000,Schedule!$D$2:$D$2000,$A4,Schedule!$B$2:$B$2000,D$3) | E4: =SUMIFS(Schedule!$I$2:$I$2000,Schedule!$D$2:$D$2000,$A4,Schedule!$B$2:$B$2000,E$3) | F4: =SUMIFS(Schedule!$I$2:$I$2000,Schedule!$D$2:$D$2000,$A4,Schedule!$B$2:$B$2000,F$3) | G4: =SUMIFS(Schedule!$I$2:$I$2000,Schedule!$D$2:$D$2000,$A4,Schedule!$B$2:$B$2000,G$3) | H4: =SUMIFS(Schedule!$I$2:$I$2000,Schedule!$D$2:$D$2000,$A4,Schedule!$B$2:$B$2000,H$3) | I4: =SUMIFS(Schedule!$I$2:$I$2000,Schedule!$D$2:$D$2000,$A4,Schedule!$B$2:$B$2000,I$3) | J4: =SUMIFS(Schedule!$I$2:$I$2000,Schedule!$D$2:$D$2000,$A4,Schedule!$B$2:$B$2000,J$3) | K4: =SUM(D4:J4) | L4: 40 | M4: =IF(AND(L4<>"",K4>L4),"OVER","") | N4: =SUMIFS(Schedule!$K$2:$K$2000,Schedule!$D$2:$D$2000,$A4,Schedule!$L$2:$L$2000,$B$1)
A5: EMP-002 | B5: Jordan Lee | C5: Shift Lead | D5: =SUMIFS(Schedule!$I$2:$I$2000,Schedule!$D$2:$D$2000,$A5,Schedule!$B$2:$B$2000,D$3) | E5: =SUMIFS(Schedule!$I$2:$I$2000,Schedule!$D$2:$D$2000,$A5,Schedule!$B$2:$B$2000,E$3) | F5: =SUMIFS(Schedule!$I$2:$I$2000,Schedule!$D$2:$D$2000,$A5,Schedule!$B$2:$B$2000,F$3) | G5: =SUMIFS(Schedule!$I$2:$I$2000,Schedule!$D$2:$D$2000,$A5,Schedule!$B$2:$B$2000,G$3) | H5: =SUMIFS(Schedule!$I$2:$I$2000,Schedule!$D$2:$D$2000,$A5,Schedule!$B$2:$B$2000,H$3) | I5: =SUMIFS(Schedule!$I$2:$I$2000,Schedule!$D$2:$D$2000,$A5,Schedule!$B$2:$B$2000,I$3) | J5: =SUMIFS(Schedule!$I$2:$I$2000,Schedule!$D$2:$D$2000,$A5,Schedule!$B$2:$B$2000,J$3) | K5: =SUM(D5:J5) | L5: 40 | M5: =IF(AND(L5<>"",K5>L5),"OVER","") | N5: =SUMIFS(Schedule!$K$2:$K$2000,Schedule!$D$2:$D$2000,$A5,Schedule!$L$2:$L$2000,$B$1)
A6: EMP-003 | B6: Sam Patel | C6: Juicer | D6: =SUMIFS(Schedule!$I$2:$I$2000,Schedule!$D$2:$D$2000,$A6,Schedule!$B$2:$B$2000,D$3) | E6: =SUMIFS(Schedule!$I$2:$I$2000,Schedule!$D$2:$D$2000,$A6,Schedule!$B$2:$B$2000,E$3) | F6: =SUMIFS(Schedule!$I$2:$I$2000,Schedule!$D$2:$D$2000,$A6,Schedule!$B$2:$B$2000,F$3) | G6: =SUMIFS(Schedule!$I$2:$I$2000,Schedule!$D$2:$D$2000,$A6,Schedule!$B$2:$B$2000,G$3) | H6: =SUMIFS(Schedule!$I$2:$I$2000,Schedule!$D$2:$D$2000,$A6,Schedule!$B$2:$B$2000,H$3) | I6: =SUMIFS(Schedule!$I$2:$I$2000,Schedule!$D$2:$D$2000,$A6,Schedule!$B$2:$B$2000,I$3) | J6: =SUMIFS(Schedule!$I$2:$I$2000,Schedule!$D$2:$D$2000,$A6,Schedule!$B$2:$B$2000,J$3) | K6: =SUM(D6:J6) | L6: 40 | M6: =IF(AND(L6<>"",K6>L6),"OVER","") | N6: =SUMIFS(Schedule!$K$2:$K$2000,Schedule!$D$2:$D$2000,$A6,Schedule!$L$2:$L$2000,$B$1)
A7: EMP-004 | B7: Alex Kim | C7: Juicer | D7: =SUMIFS(Schedule!$I$2:$I$2000,Schedule!$D$2:$D$2000,$A7,Schedule!$B$2:$B$2000,D$3) | E7: =SUMIFS(Schedule!$I$2:$I$2000,Schedule!$D$2:$D$2000,$A7,Schedule!$B$2:$B$2000,E$3) | F7: =SUMIFS(Schedule!$I$2:$I$2000,Schedule!$D$2:$D$2000,$A7,Schedule!$B$2:$B$2000,F$3) | G7: =SUMIFS(Schedule!$I$2:$I$2000,Schedule!$D$2:$D$2000,$A7,Schedule!$B$2:$B$2000,G$3) | H7: =SUMIFS(Schedule!$I$2:$I$2000,Schedule!$D$2:$D$2000,$A7,Schedule!$B$2:$B$2000,H$3) | I7: =SUMIFS(Schedule!$I$2:$I$2000,Schedule!$D$2:$D$2000,$A7,Schedule!$B$2:$B$2000,I$3) | J7: =SUMIFS(Schedule!$I$2:$I$2000,Schedule!$D$2:$D$2000,$A7,Schedule!$B$2:$B$2000,J$3) | K7: =SUM(D7:J7) | L7: 30 | M7: =IF(AND(L7<>"",K7>L7),"OVER","") | N7: =SUMIFS(Schedule!$K$2:$K$2000,Schedule!$D$2:$D$2000,$A7,Schedule!$L$2:$L$2000,$B$1)
